Workbook

Sheet 说明
A1: 待入库拍照手记 → 录入底稿
A2: 来源：/private/tmp/待入库拍照图 共 17 张照片（IMG_3087 ~ IMG_3103）
A4: 用途 | B4: 这份表是「手写记账本 → 系统录入」的中间底稿。字段名和取值都按 ry-vue 库的 wms_item / wms_item_sku / wms_item_brand / wms_item_category 结构来对齐，确认后可直接生成入库单。
A6: 先看哪一列 | B6: ① 先看【存疑/需确认】列（黄底）——这些是我认不准或原稿本身有涂改的；② 再看【系统比对结果】列。
A8: 系统比对结果 | B8: 已存在（可直接入库）= 绿底，分类+SKU+品牌 都能在库里找到； 需新建SKU / 需新建分类 = 橙底； SKU已存在但该品牌下没有 = 需要给这个品牌建一条商品。
A11: 数量列 | B11: 凡是原稿写成多笔相加的（如「5+12个」「24+81=105」），【数量】列写的是 Excel 公式，改任一加数会自动重算；【数量原文】保留手写原样。
A13: 单价列 | B13: 只有 IMG_3087 / IMG_3088 / IMG_3089 三页记了单价。原稿里有些写成「94-61」这种两个数，我没有猜，原样放在【单价原文】里，【单价(元)】留空等你确认。IMG_3090 以后各页原稿都没有单价。
A15: 品牌简写 | B15: 原稿用「山 / 东 / 气 / YYC / 三正」等简写，对照关系见【品牌对照】页。其中「山」的归属有风险，务必先确认。
A17: 确认列 | B17: 最右边黄色【确认】列留给你打勾（填 OK / 改 / 删）。
A19: 示例行 | B19: 序号 20 | IMG_3087 | 4 | TN 32X20S 10个 ✓ 53 | TN双杆气缸（亚德客型） | TN双杆气缸 | （空） | TN32-20 | 10个 | 10 | 个 | 53 | 53.00 | 已存在（可直接入库） | （空） | OK
A22: 数据统计
A23: 明细总行数 | B23: =COUNTA(待入库明细!A2:A109) -> 108
A24: 数量合计（件） | B24: =SUM(待入库明细!J2:J109) -> 7170
A25: 有存疑标注的行数 | B25: =COUNTIF(待入库明细!O2:O109,"*") -> 37
A26: 可直接入库的行数 | B26: =COUNTIF(待入库明细!N2:N109,"已存在*") -> 0
A27: 需新建SKU的行数 | B27: =COUNTIF(待入库明细!N2:N109,"需新建SKU") -> 98
A28: 需新建分类的行数 | B28: =COUNTIF(待入库明细!N2:N109,"需新建分类") -> 10
A29: 需给该品牌建商品 | B29: =COUNTIF(待入库明细!N2:N109,"SKU已存在，但该品牌下没有*") -> 0

Sheet 待入库明细
A1: 序号 | B1: 照片 | C1: 页内行 | D1: 原始手写记录 | E1: 建议分类 | F1: 建议商品名称 | G1: 品牌 | H1: 建议SKU/规格 | I1: 数量原文 | J1: 数量 | K1: 单位 | L1: 单价原文 | M1: 单价(元) | N1: 系统比对结果 | O1: 存疑/需确认 | P1: 确认
A2: 9 | B2: IMG_3087 | C2: 9 | D2: 自动排水器 XFC400 43个 | E2: 气源处理类 | F2: 自动排水器 | H2: XFC400 | I2: 43个 | J2: 43 | K2: 个 | N2: 需新建SKU
A3: 30 | B3: IMG_3088 | C3: 11 | D3: MHY2-20D 1个 | E3: 手指气缸 | F3: MHY2 气动手指 | H3: MHY2-20D | I3: 1个 | J3: 1 | K3: 个 | N3: 需新建分类 | O3: 型号首字被涂改，疑为 MHY2-20D；单价两个数
A4: 31 | B4: IMG_3088 | C4: 12 | D4: HFZ-16D 1个 | E4: 手指气缸 | F4: HFZ 气动手指 | H4: HFZ-16D | I4: 1个 | J4: 1 | K4: 个 | N4: 需新建分类 | O4: 单价两个数
A5: 34 | B5: IMG_3088 | C5: 15 | D5: 2分牙 50表面 10kg 1MPa 109个 | E5: 油压表 | F5: 压力表 | H5: 2分牙50面板 10kg/1MPa | I5: 109个 | J5: 109 | K5: 个 | N5: 需新建SKU | O5: 是压力表/气压表，分类待定
A6: 35 | B6: IMG_3088 | C6: 16 | D6: Q22XD-2L 220V 全铜 118个 | E6: 电磁水阀 | F6: 先导阀 | H6: Q22XD-2L 220V 全铜 | I6: 118个 | J6: 118 | K6: 个 | N6: 需新建SKU
A7: 36 | B7: IMG_3088 | C7: 17 | D7: Q23XD-2L 220V 全铜 1个 | E7: 电磁水阀 | F7: 先导阀 | H7: Q23XD-2L 220V 全铜 | I7: 1个 | J7: 1 | K7: 个 | N7: 需新建SKU | O7: 该行仅写「23」和「1个」，含义不明，需现场核对
A8: 37 | B8: IMG_3088 | C8: 18 | D8: FDF-8 220V 8个 | E8: 气动电磁阀 | F8: FDF 制冷电磁阀 | H8: FDF-8 220V | I8: 8个 | J8: 8 | K8: 个 | N8: 需新建分类
A9: 38 | B9: IMG_3088 | C9: 19 | D9: FB2E-V 220V 3分牙 24个 | E9: 气动电磁阀 | F9: FB2E-V 常闭电磁阀 | H9: FB2E-V 220V 3分牙 | I9: 2+14+6+4 | J9: =2+14+6+4 -> 26 | K9: 个 | N9: 需新建分类 | O9: 数量为多笔相加，字迹潦草，请复核
A10: 39 | B10: IMG_3088 | C10: 20 | D10: FB2E-V 220V 2分牙 24个 | E10: 气动电磁阀 | F10: FB2E-V 常闭电磁阀 | H10: FB2E-V 220V 2分牙 | I10: 24个 | J10: 24 | K10: 个 | N10: 需新建分类 | O10: 数量有涂改
A11: 40 | B11: IMG_3089 | C11: 1 | D11: HR30 23个 | E11: 配件 | F11: HR30 缓冲器 | H11: HR30 | I11: 22+1 | J11: =22+1 -> 23 | K11: 个 | N11: 需新建SKU
A12: 42 | B12: IMG_3089 | C12: 3 | D12: US-25 220V 29个 | E12: 气动电磁阀 | F12: US 蒸汽电磁阀 | H12: US-25 220V | I12: 29个 | J12: 29 | K12: 个 | N12: 需新建SKU
A13: 43 | B13: IMG_3089 | C13: 4 | D13: US-20 220V 13个 | E13: 气动电磁阀 | F13: US 蒸汽电磁阀 | H13: US-20 220V | I13: 13个 | J13: 13 | K13: 个 | N13: 需新建SKU
A14: 44 | B14: IMG_3089 | C14: 5 | D14: US-20K 220V 常开 9个 | E14: 气动电磁阀 | F14: US 蒸汽电磁阀 | H14: US-20K 220V 常开 | I14: 9个 | J14: 9 | K14: 个 | N14: 需新建SKU | O14: 无单价
A15: 45 | B15: IMG_3089 | C15: 6 | D15: DQK 1442 1个 | E15: 气动电磁阀 | F15: DQK 电磁阀 | H15: DQK1442 | I15: 1个 | J15: 1 | K15: 个 | N15: 需新建SKU
A16: 46 | B16: IMG_3089 | C16: 7 | D16: DQK 2422 7个 | E16: 气动电磁阀 | F16: DQK 电磁阀 | H16: DQK2422 | I16: 7个 | J16: 7 | K16: 个 | N16: 需新建SKU | O16: 无单价
A17: 47 | B17: IMG_3089 | C17: 8 | D17: DQK 1422 220V 10个 67 | E17: 气动电磁阀 | F17: DQK 电磁阀 | H17: DQK1422 220V | I17: 10个 | J17: 10 | K17: 个 | N17: 需新建SKU
A18: 48 | B18: IMG_3089 | C18: 9 | D18: JYC牌 SFC2000-1/4 三联体 9个 | E18: 气动电磁阀 | F18: 三联体 | G18: JYC | H18: SFC2000-1/4 | I18: 9个 | J18: 9 | K18: 个 | N18: 需新建SKU | O18: 型号中间字迹涂改，疑为 SFC
A19: 49 | B19: IMG_3089 | C19: 10 | D19: 百灵 二联件 2010-02 28个 | E19: 调压过滤器（二联件） | F19: 调压过滤器 | G19: 百灵（BLCH） | H19: 2010-02 | I19: 28个 | J19: 28 | K19: 个 | N19: 需新建SKU
A20: 50 | B20: IMG_3089 | C20: 11 | D20: 百灵 AFR2000-02 295个 49 | E20: 调压过滤器（二联件） | F20: 调压过滤器 | G20: 百灵（BLCH） | H20: AFR2000-02 | I20: 295个 | J20: 295 | K20: 个 | N20: 需新建SKU
A21: 51 | B21: IMG_3089 | C21: 12 | D21: DQK 1322 24V 1个 67 | E21: 气动电磁阀 | F21: DQK 电磁阀 | H21: DQK1322 24V | I21: 1个 | J21: 1 | K21: 个 | N21: 需新建SKU
A22: 62 | B22: IMG_3090 | C22: 10 | D22: 抽油泵 3-PHASE 1/4HP 1 | E22: 抽油泵 | F22: 抽油泵 | H22: 3-PHASE 1/4HP | I22: 1 | J22: 1 | K22: 台 | N22: 需新建分类
A23: 70 | B23: IMG_3091 | C23: 1 | D23: 卓良 MSV-86522R 机械阀 1 | E23: 手动阀 | F23: 气动手动阀 | G23: 卓良(zholo) | H23: MSV-86522R | I23: 1 | J23: 1 | K23: 个 | N23: 需新建SKU | O23: 整页无单价
A24: 71 | B24: IMG_3091 | C24: 2 | D24: 盛达 SD250612 机械阀 13 | E24: 手动阀 | F24: 气动手动阀 | G24: 盛达(SDPC) | H24: SD250612 | I24: 13 | J24: 13 | K24: 个 | N24: 需新建SKU
A25: 72 | B25: IMG_3091 | C25: 3 | D25: 盛达 S230805A 推拉手动阀 9 | E25: 手动阀 | F25: 气动手动阀 | G25: 盛达(SDPC) | H25: S230805A | I25: 9 | J25: 9 | K25: 个 | N25: 需新建SKU
A26: 73 | B26: IMG_3091 | C26: 4 | D26: 盛达 JM-02 机械阀 4 | E26: 手动阀 | F26: 气动手动阀 | G26: 盛达(SDPC) | H26: JM-02 | I26: 4 | J26: 4 | K26: 个 | N26: 需新建SKU
A27: 74 | B27: IMG_3091 | C27: 5 | D27: 盛达 MOV-02 机械阀 30 | E27: 手动阀 | F27: 气动手动阀 | G27: 盛达(SDPC) | H27: MOV-02 | I27: 30 | J27: 30 | K27: 个 | N27: 需新建SKU
A28: 75 | B28: IMG_3091 | C28: 6 | D28: 盛达 JM-01 机械阀 12 | E28: 手动阀 | F28: 气动手动阀 | G28: 盛达(SDPC) | H28: JM-01 | I28: 12 | J28: 12 | K28: 个 | N28: 需新建SKU | O28: 数量前有涂改
A29: 76 | B29: IMG_3091 | C29: 7 | D29: 盛达 S230805 16 | E29: 手动阀 | F29: 气动手动阀 | G29: 盛达(SDPC) | H29: S230805 | I29: 16 | J29: 16 | K29: 个 | N29: 需新建SKU
A30: 77 | B30: IMG_3091 | C30: 8 | D30: 盛达S0230605A 2+2+15 | E30: 手动阀 | F30: 气动手动阀 | H30: S0230605A | I30: 2+2+15 | J30: =2+2+15 -> 19 | K30: 个 | N30: 需新建SKU | O30: 数量末位字迹潦草，请复核
A31: 78 | B31: IMG_3091 | C31: 9 | D31: 照庆 Q25 R5-L6 推拉阀 1+1 | E31: 手动阀 | F31: 气动手动阀 | G31: 照庆 | H31: Q25 RS-L6 | I31: 1+1 | J31: =1+1 -> 2 | K31: 个 | N31: 需新建SKU | O31: 品牌两字辨认为「熙庆」，库中无此品牌，请确认
A32: 79 | B32: IMG_3091 | C32: 10 | D32: 无(品牌) 3R210-08 推拉阀 34 | E32: 手动阀 | F32: 气动手动阀 | G32: 无 | H32: 3R210-08 | I32: 34 | J32: 34 | K32: 个 | N32: 需新建SKU | O32: 型号前有涂改
A33: 80 | B33: IMG_3091 | C33: 11 | D33: 无(品牌) 4R210-08 22 推拉阀 | E33: 手动阀 | F33: 气动手动阀 | G33: 无 | H33: 4R210-08 | I33: 22 | J33: 22 | K33: 个 | N33: 需新建SKU
A34: 81 | B34: IMG_3091 | C34: 12 | D34: QTYH-08 0.5-30MPa 1 | E34: 调压阀 | F34: QTYH 调压阀 | H34: QTYH-08 0.5-30MPa | I34: 1 | J34: 1 | K34: 个 | N34: 需新建SKU
A35: 82 | B35: IMG_3091 | C35: 13 | D35: AF2000 30 | E35: 气源处理类 | F35: AF 过滤器 | H35: AF2000 | I35: 30 | J35: 30 | K35: 个 | N35: 需新建SKU
A36: 83 | B36: IMG_3091 | C36: 14 | D36: AL2000 3 | E36: 气源处理类 | F36: AL 油雾器 | H36: AL2000 | I36: 3 | J36: 3 | K36: 个 | N36: 需新建SKU
A37: 84 | B37: IMG_3091 | C37: 15 | D37: 针闭式油杯 B型 50cm² M14X1.5 2 | E37: 润滑器 | F37: 斜阀式油杯 | H37: B型 50cm² M14X1.5 | I37: 2 | J37: 2 | K37: 个 | N37: 需新建SKU
A38: 85 | B38: IMG_3091 | C38: 16 | D38: 针闭式油杯 B型 25cm² M14X1.5 20 | E38: 润滑器? | F38: 斜阀式油杯 | H38: B型 25cm² M14X1.5 | I38: 20 | J38: 20 | K38: 个 | N38: 需新建SKU
A39: 86 | B39: IMG_3091 | C39: 17 | D39: AC3660-2 缓冲器 2 | E39: 配件? | F39: 缓冲器 | H39: AC3660-2 | I39: 2 | J39: 2 | K39: 个 | N39: 需新建SKU
A40: 87 | B40: IMG_3091 | C40: 18 | D40: HR-60 1 | E40: 配件? | F40: 缓冲器 | H40: HR-60 | I40: 1 | J40: 1 | K40: 个 | N40: 需新建SKU
...

Sheet 品牌对照
A1: 手写写法 | B1: 对应系统品牌 | C1: 品牌ID | D1: 库中已有 | E1: 说明
A2: 山 / 山耐斯 | B2: 山耐斯 | C2: 1950103572305715201 | D2: 是 | E2: ⚠ 库中同类快插接头几乎都挂在【山克斯（SUNCOS）】下，山耐斯 只用在手动阀/脚踏阀/调压过滤器。请确认手写的「山」到底指哪个品牌——选错会产生重复商品。
A3: YYC | B3: 亚一气动（YYC） | C3: 1966772332903120897 | D3: 是
A4: 气 / 气动之星 | B4: 气动之星（CYKL） | C4: 1966314725293801474 | D4: 是
A5: 东 | B5: 东特 | C5: 1945334660456259585 | D5: 是 | E5: 库中绝大多数快插接头的默认品牌
A6: 三正 | B6: 三正气动 | C6: 1961340546236592129 | D6: 是
A7: SUNCOS | B7: 山克斯（SUNCOS） | C7: 1966314533442142210 | D7: 是
A8: 卓良 | B8: 卓良(zholo) | C8: 1950103450909974529 | D8: 是
A9: 盛达 | B9: 盛达(SDPC) | C9: 1946830584529588226 | D9: 是
A10: 百灵 | B10: 百灵（BLCH） | C10: 1961752675691331586 | D10: 是
A11: JYC | B11: JYC | C11: 1957282155310661633 | D11: 是
A12: 无 | B12: （不填品牌） | D12: — | E12: 手写标「无」，表示无品牌
A13: 熙庆(?) | B13: — | D13: 否 | E13: ⚠ IMG_3091 第9行，两字辨认为「熙庆」，库中无此品牌，请确认后新建或改正
A14: （空白） | B14: （不填品牌） | D14: — | E14: 原始记录未标品牌，入库时需现场判断

Sheet 存疑清单
A1: 明细序号 | B1: 照片 | C1: 原始手写记录 | D1: 存疑内容
A2: 1 | B2: IMG_3087 | C2: MGPM 25X75 三轴气缸 13个 ✓ 94-61 | D2: 红笔记录；单价写成两个数(94/61)，需确认哪个是成本价；分类需新建
A3: 2 | B3: IMG_3087 | C3: TN 32X100S 1分 2个 ✓ 89-99 | D3: 原文尾部带 S；单价两个数(89/99) 待确认
A4: 3 | B4: IMG_3087 | C4: TN 32X25S 5个 ✓ 55-95 | D4: 单价两个数待确认
A5: 7 | B5: IMG_3087 | C5: TN 32X30S 5个 ✓ 55 | D5: 数量原写58后改5，请确认
A6: 10 | B6: IMG_3087 | C6: TN 25X25S 1分 5+12个 ✓ 45 | D6: 数量两笔 5+12
A7: 11 | B7: IMG_3087 | C7: TN 25X15S 30(涂改)…个 ✓ 40/42 | D7: 数量被涂改无法辨认，必须现场点数；单价 40 改 42
A8: 17 | B8: IMG_3087 | C8: TN 20X25S M5 8个 ✓ 32 | D8: 备注 M5 接口
A9: 21 | B9: IMG_3088 | C9: TN 16X25S M5 8个 ✓ 25 | D9: 备注 M5
A10: 24 | B10: IMG_3088 | C10: TN 10X15S M5 3个 ✓ 22 | D10: 备注 M5
A11: 29 | B11: IMG_3088 | C11: MGPM 20X20S 23个 ✓ 33-50 | D11: 单价两个数待确认
A12: 30 | B12: IMG_3088 | C12: MHY2-20D 1个 89-128 | D12: 型号首字被涂改，疑为 MHY2-20D；单价两个数
A13: 31 | B13: IMG_3088 | C13: HFZ-16D 1个 65-51 | D13: 单价两个数
... A113: 308 | B113: IMG_3103 | C113: PL 4-02 250 | D113: 数量前有一串被划掉

Sheet 系统现有分类
A1: 系统分类 | B1: 该分类下已有商品（商品名 / 品牌）
A2: ACQ薄型气缸 | B2: ACQ薄型气缸（威特）
A3: C式接头 | B3: C式接头（JCP） ；C式接头（TRM） ；C式接头（新禾） ；C式接头（明铁）
A4: C式自锁接头 | B4: C式自锁接头 ；C式自锁接头（明铁）
A5: DHVFF手阀 | B5: DHVFF手阀（东特）
A6: DPCF内螺纹直通 | B6: PCF内螺纹直通（三正气动） ；PCF内螺纹直通（东特） ；PCF内螺纹直通（山克斯（SUNCOS））
A7: DPC螺纹直通 | B7: PC螺纹直通（Xing） ；PC螺纹直通（东特） ；PC螺纹直通（亿日） ；PC螺纹直通（气动之星（CYKL）） ；SPC螺纹直通（山克斯（SUNCOS））
A8: DPE-T型三通 | B8: DPE T型三通（东特） ；PE T型三通（山克斯（SUNCOS）） ；PE Y型三通（亚一气动（YYC））
A9: DPG-变径直通 | B9: PG 变径直通（东特） ；PG变经直通（亚一气动（YYC）） ；PG变经直通（山克斯（SUNCOS）） ；PG变经直通（气动之星（CYKL））
A10: DPKB螺纹五通变径 | B10: DPKB螺纹五通变径（东特）
A11: DPKD螺纹五通 | B11: DPKD螺纹五通（东特）
A12: DPKG五通变径 | B12: DPKG五通变径（东特）
... A88: 齿轮泵 | B88: 齿轮泵
